[2023-10-22T20:41:35.756+0400] {taskinstance.py:1159} INFO - Dependencies all met for dep_context=non-requeueable deps ti=<TaskInstance: iris_score.get_data manual__2023-10-22T16:41:33.660598+00:00 [queued]>
[2023-10-22T20:41:35.758+0400] {taskinstance.py:1159} INFO - Dependencies all met for dep_context=requeueable deps ti=<TaskInstance: iris_score.get_data manual__2023-10-22T16:41:33.660598+00:00 [queued]>
[2023-10-22T20:41:35.758+0400] {taskinstance.py:1361} INFO - Starting attempt 1 of 2
[2023-10-22T20:41:35.766+0400] {taskinstance.py:1382} INFO - Executing <Task(BashOperator): get_data> on 2023-10-22 16:41:33.660598+00:00
[2023-10-22T20:41:35.767+0400] {standard_task_runner.py:57} INFO - Started process 8164 to run task
[2023-10-22T20:41:35.770+0400] {standard_task_runner.py:84} INFO - Running: ['airflow', 'tasks', 'run', 'iris_score', 'get_data', 'manual__2023-10-22T16:41:33.660598+00:00', '--job-id', '12', '--raw', '--subdir', 'DAGS_FOLDER/iris_score.py', '--cfg-path', '/tmp/tmprn0tudei']
[2023-10-22T20:41:35.771+0400] {standard_task_runner.py:85} INFO - Job 12: Subtask get_data
[2023-10-22T20:41:35.839+0400] {task_command.py:416} INFO - Running <TaskInstance: iris_score.get_data manual__2023-10-22T16:41:33.660598+00:00 [running]> on host primary
[2023-10-22T20:41:35.863+0400] {taskinstance.py:1662} INFO - Exporting env vars: AIRFLOW_CTX_DAG_OWNER='admin' AIRFLOW_CTX_DAG_ID='iris_score' AIRFLOW_CTX_TASK_ID='get_data' AIRFLOW_CTX_EXECUTION_DATE='2023-10-22T16:41:33.660598+00:00' AIRFLOW_CTX_TRY_NUMBER='1' AIRFLOW_CTX_DAG_RUN_ID='manual__2023-10-22T16:41:33.660598+00:00'
[2023-10-22T20:41:35.864+0400] {subprocess.py:63} INFO - Tmp dir root location: /tmp
[2023-10-22T20:41:35.864+0400] {subprocess.py:75} INFO - Running command: ['/usr/bin/bash', '-c', 'python3 /home/pyretttt/repos/mlops3/scripts/get_data.py']
[2023-10-22T20:41:35.867+0400] {subprocess.py:86} INFO - Output:
[2023-10-22T20:41:36.260+0400] {subprocess.py:93} INFO - /home/pyretttt/repos/mlops3/env/lib/python3.10/site-packages/pydantic/_internal/_fields.py:128: UserWarning: Field "model_server_url" has conflict with protected namespace "model_".
[2023-10-22T20:41:36.260+0400] {subprocess.py:93} INFO - 
[2023-10-22T20:41:36.260+0400] {subprocess.py:93} INFO - You may be able to resolve this warning by setting `model_config['protected_namespaces'] = ()`.
[2023-10-22T20:41:36.260+0400] {subprocess.py:93} INFO -   warnings.warn(
[2023-10-22T20:41:36.263+0400] {subprocess.py:93} INFO - /home/pyretttt/repos/mlops3/env/lib/python3.10/site-packages/pydantic/_internal/_config.py:317: UserWarning: Valid config keys have changed in V2:
[2023-10-22T20:41:36.263+0400] {subprocess.py:93} INFO - * 'schema_extra' has been renamed to 'json_schema_extra'
[2023-10-22T20:41:36.263+0400] {subprocess.py:93} INFO -   warnings.warn(message, UserWarning)
[2023-10-22T20:41:36.761+0400] {subprocess.py:97} INFO - Command exited with return code 0
[2023-10-22T20:41:36.771+0400] {taskinstance.py:1400} INFO - Marking task as SUCCESS. dag_id=iris_score, task_id=get_data, execution_date=20231022T164133, start_date=20231022T164135, end_date=20231022T164136
[2023-10-22T20:41:36.808+0400] {local_task_job_runner.py:228} INFO - Task exited with return code 0
[2023-10-22T20:41:36.856+0400] {taskinstance.py:2778} INFO - 1 downstream tasks scheduled from follow-on schedule check
